
const fail=()=>{
  return Promise.reject('x');
}

Promise.resolve(
  fail()
).then(
  x => console.log('resolve', x)
).catch(console.error);

